Workbook
Name A: [1]MRD!$A$1:$BB$1866
Name A: [1]MRD!$A$1:$BB$1866
Name MRD: [2]MRD!$A$1:$BB$2983
Name MRD: [3]MRD!$A$1:$BB$2167

Sheet Requisiciones
A1: Número Requisicion | B1: Empresa | C1: Unidad | D1: Fecha Recepción | E1: Fecha de aprobación Requisición | F1: Regional | G1: Ciudad | H1: Tipo Servicio | I1: Cargo Solicitado | J1: Tipo Cargo Solicitado | K1: Psicologo Responsable | L1: # Personas Solicitadas | M1: Estado Requisición | N1: Fecha Afinamiento Perfil | O1: # hojas de vida presentadas al cliente | P1: ¿Pertenece a la Primera Terna? | Q1: Fecha entrega hoja de vida al cliente | R1: Fecha de aprobación de HV por el cliente | S1: Número de hojas de vida aprobadas por el cliente | T1: Fecha de envio del perfil | U1: Fecha Publicación de Concurso | V1: Fecha entrega matriz de inscritos | W1: Fecha Notificación quienes continúan a prueba técnica | X1: Fecha aplicación Prueba técnica | Y1: Fecha envío prueba técnica al cliente | Z1: Fecha Notificación quienes continúan a proceso de selección | AA1: Número de personas evaluadas | AB1: Número de informes entregados | AC1: Número de referencias | AD1: Fecha de entrega de informe al cliente | AE1: Fecha de notificación del cliente persona seleccionada | AF1: Fecha de solicitud contratacion | AG1: Fecha Firma Contrato o Cierre de requisición | AH1: Fecha de Ingreso | AI1: Mes | AJ1: Candidato(s) contratado(s): | AK1: Observacion | AL1: Efectividad reclutamiento | AM1: Oportunidad en el proceso de reclutamiento | AN1: Oportunidad en proceso de Selección | AO1: Dias a Descontar Selección | AP1: Oportunidad Selección | AQ1: Oportunidad en proceso de Contratación | AR1: Dias a Descontar Contratación | AS1: Oportunidad Contratacion | AT1: Tiempo Total Proceso | AU1: Oportunidad SyC | AV1: Fuente de Reclutamiento | AW1: Ultima empresa donde trabajó | AX1: Candidato 1 | AY1: Candidato 2 | AZ1: Candidato 3 | BA1: Candidato 4 | BB1: Candidato 5
A2: 14104 | B2: FUNDACION COOMEVA | C2: FUNDACION COOMEVA | D2: 45909 | E2: 45797 | F2: Medellin | G2: MEDELLIN | H2: VACANTE DESDE RECLUTAMIENTO | I2: SUPERNUMERARIO/A | J2: CARGO COMERCIAL | K2: Fredy Alejandro Villada Posada | L2: 1 | M2: Finalizado - Llego hasta contratacion | N2: 0000-00-00 | O2: 18 | P2: No | Q2: 46027 | R2: 46027 | S2: 15 | T2: 0000-00-00 | U2: 0000-00-00 | V2: 0000-00-00 | W2: 0000-00-00 | X2: 0000-00-00 | Y2: 0000-00-00 | Z2: 0000-00-00 | AA2: 5 | AB2: 5 | AC2: 0 | AD2: 46031 | AE2: 46037 | AF2: 46037 | AG2: 46048 | AH2: 46048 | AI2: =MONTH(AH2) -> 1 | AJ2: Juan Camilo Cuartas Echeverri | AK2: 20250520: GH solicita reclutamiento, se le solicita a GH el aval del corporativo para continuar. 20250521: Se detiene vacante hasta tener aval del corporativo. 20250618: Se reanuda proceso por cargo en estructura de la empresa, pdte enviar reclutamiento. 20250624: Se envian 3 HV (Tatiana, Isabella, Cristian), pdte retro GH. 20250701: gh solicita realizar prueba tecnica de Isabella Gonzales y Cristian Amaguaña. 20250702: se adjunta prueba tecnica. pte retro por gh. 20250704: solicitan evaluar a isabella para Analista Reg Microcredito FUN y Cristian no avanza prueba tecnica. Se activa reclutamiento. 20250707: Se envia 2 hv. pte retro por gh. 20250715: gh envia retro y solicita avanzar a prueba tecnica con Juan Carlos Roman. 20250717: se envia prueba tecnica de Juan Roman. Pte retro por gh. 20250724: gh solicita reasignar requi a la Ciudad de Medellin por cambio de la pocision. 20250724: GH notifica el cambio de RQ para la ciudad de Medellin, se informa que se tendrá en cuenta los candidatos en back de la vacante como Analista de Microcredito. 20250728: se hace el ofrecimiento a la candidata Luby Dayana Guisao quien acepta, sin embargo, se hace validacion con JI para valorar la disponibilidad de viajar. 20250801: candidata se presenta a entrevista, sin embargo, por solicitud de JI se solicita buscar nuevos candidatos considerando que la candidata podría no cumplir con los requisitos para la disponibilidad de viaje. 20250805: se comparte 1 HV a la espera de disponibilidad para entrevista. 20250806: se programa entrevista para el viernes 8 de ago. 20250811: Gh indica que no fue posible conectarse al espacio. 20250812: JI solicita programar la entrevista para el miércoles 13 y se comparten 2 HV (Marlon Pacheco) adicionales. 20250813: se presenta el candidato Marlon Pacheco y continua proceso para aplicar PS. 20250819: se comparte retroliamentacion con concepto aprobado de Marlon Pacheco 20250822: se solicita retroalimentacion a GH y JI. 20250825: JI manfiesta la intención de que el candidato sea contratado en la RQ 14772 para Analista Regional. 20250826: se continua reclutamiento. 20250827: JI mangiiesta que el candidato Marlon Pacheco desea continuar el proceso para supernumerario, sin embargo, el candidato no responde los mensajes 20250829: se comparten 2 HV para entrevista el 2 de sep. 20250902: se presetan dos candidatos, pero no aprueban proceso de entrevista. 20250908: se envían 3 HV para entrevista el 9 de sep. 20250909: se presentan dos candidatos, uno aprueba el proceso pero será tenido en cuenta para la RQ 14772 Ana de Microcrédito. 20250911: se comparte 1 HV adicional (Felipe Guerra) 20250916: se comparte otra HV (Brayan Baron) y se programa entrevista para el día de hoy. Se presentan los dos candidatos, sin embargo, no aprueban proceso de entrevista iniguno de los dos. 20250922: se comparte 1 HV para considerar y se continua reclutamiento. 20250930: se programa entrevista para el 1 de oct solo con GH por falta de disponibilidad de JI y se comparte 1 HV más 20251001: se presenta 1 candidato, pero no aprueba proceso, se programa otra entrevista para el 2 de octubre y se comparte 1 Hv adicional. 20251002: se presenta 1 candidato y no aprueba proceso 20251006: se continua con reclutamiento. 20251014: se continua proceso reclutamiento ya que no hay candidatos que cumplan con el perfil.20251020: se comparte 1 HV, sin embargo, se hace validación previa ya que requiere excepción en el perfil académico y GH informa que debe cumplir con el perfil requerido 20251023: se comparte 1 HV y se programa entrevista para el 24 de oct. 20251024: se presenta el candidato pero no aprueba entrevista. 20251028: se continua reclutamiento 20251030: se continua reclutamiento 20251104: se comparte 1 HV. 20251107: candidata de la HV pendiente indica que no tiene aún disponibilidad para iniciar el proceso 20251111: candidata inidica que cuenta con disponibilidad para el 12 de nov 20251112: se presenta la candidata, pero no aprueba proceso de entrevista 20251118: se continua reclutamiento 20251124: continua reclutamiento. 20251127: se comparte 1 HV adicional para entrevista el 1 de dic. 20251201: el candidato programado no se conecta al espacio de entrevista. 20251209: se continua reclutamiento 20251212: se comparte 1 HV para ser tenida en cuenta. 20251229: Se compartio una hoja de vida pendiente de la retroalimentacion de GH 20260105: se comparte 1 HV para entrevista el 6 de enero. 20260106: se presenta Juan Camilo Cuartas y aprueba entrevista con GH, solicita programar evaluacion.20260109: se comparte retroalimentacion con concepto aprobado 20250114: se valida con GH e indican que están aun a la espera de confirmar la posibilidad de dar continuidad al candidato 20250115: GH solicita el envio a contratacion de Juan Camilo Cuartas. Se envia OC 20260119: candidato registra con novedad en ES, sin embargo, se gestiona excepcion con GH. 20260121: candidato se encuentra en apertura de cuenta y EM 20260122: candidato presenta novedad con apertura de cuenta y GH brinda autorizacion para el pago por cheque 20260123: contratacion confirma ingreso de Juan Camilo Cuartas con fecha de inicio 26 de ene | AL2: =IFERROR(S2/O2,"N/A") -> 0.83333333 | AM2: =IFERROR(NETWORKDAYS(D2,Q2,Hoja1!$A$1:$A$29),"N/A") -> 79 | AN2: =IFERROR(NETWORKDAYS(D2,AE2,Hoja1!$A$1:$A$29),"N/A") -> 86 | AO2: 10 | AP2: =AN2-AO2 -> 76 | AQ2: =IFERROR(NETWORKDAYS(AF2,AG2,Hoja1!$A$1:$A$29),"N/A") -> 8 | AR2: 3 | AS2: =AQ2-AR2 -> 5 | AT2: =IFERROR(NETWORKDAYS(D2,AG2,Hoja1!$A$1:$A$29),"N/A") -> 93 | AU2: =AT2-AO2-AR2 -> 80 | AV2: Computrabajo | AW2: Cooperativa Afroamericano | AX2: Desiste
A3: 14454 | B3: CLUB LOS ANDES | C3: CLUB LOS ANDES | D3: 45953 | E3: 45847 | F3: Cali | G3: SANTANDER DE QUILICHAO | H3: VACANTE DESDE RECLUTAMIENTO | I3: JEFE COMERCIAL | J3: JEFE/DIRECTOR/GERENTE | K3: Susan Bermeo Saenz | L3: 1 | M3: Finalizado - Llego hasta contratacion | N3: 0000-00-00 | O3: 6 | P3: No | Q3: 45968 | R3: 45968 | S3: 6 | T3: 0000-00-00 | U3: 0000-00-00 | V3: 0000-00-00 | W3: 0000-00-00 | X3: 0000-00-00 | Y3: 0000-00-00 | Z3: 0000-00-00 | AA3: 6 | AB3: 3 | AC3: 0 | AD3: 46010 | AE3: 46036 | AF3: 46036 | AG3: 46042 | AH3: 46044 | AI3: =MONTH(AH3) -> 1 | AJ3: Ricardo Carrillo Higuita | AK3: 20250709: GH solicita evaluacion de Anny Stephany Moreno Ruiz. 20250711: Anny ha realizado unicamente una prueba, solicita tiempo adicional para culminar las demas. 20250714: Se informa que la candidata tiene pendiente 2 pruebas. Se compromete a realizarlas ese mismo dia. Se agenda entrevistas para el 15 de julio. (3) 20250717: se informa a GH que la candidata no cumple perfil academico. 20250718: GH solicita no continuar y activar reclutamiento. 20250728: se envian 5 hv. 20250813: Se solicito retroaliementación del proceso. 20250815:El cliente informa que aún se encuentran revisando los perfiles. 20250820:Se solicito nuevamente retroalimentacion del proceso. 20250821:EL cliente informa que estan a la espera de la aprobacion del jefe para continuar con el proceso.(19) 20250827:El cliente envio a contratar a Anny candidata que ya estaba evaluada por Leidy Checa. Se envio a la candidata a contratación con excepción por formación academica. 20250902: La candidata no paso ES y se solicito mas hojas de vida. 20250903:Se solicita retroalimentación de las 5 hojas de vida enviadas el 28 de Julio. (22) 20250904: El cliente informa que ya reviso las HV, sin embargo pidio mas reclutamiento. (10) 20250910: Se enviaron 6 hojas de vida mas sin filtro tefonico. 20250919: Se solito retroalimentación de las hojas de vida enviadas. 20250926: Se volvio a solicitar retroalimentacion. El cliente informa que esta en entrevistas y el Lunes me da avances. (12) 20250930:El cliente envio a evaluar a Andres Tovar y David Barreros, se enviaron pruebas y se citaran a entrevista para 1 de Octubre. Andres Felipe Tovar no contesta. 20251003:Se cito a entrevista a Andres para el dia 6 de Octubre y se enviaron pruebas. (4) 20251008:David Barrios aun no ha terminado las pruebas Bluesite. (3)20251010:Se subio informe y se le informo al cliente. 20251016:El cliente entrevistara por ultima vez a David para tomar una decision. (4) 20251017:El cliente envio a contratar a David. 20251020: El candidato no ha enviado los documentos. (3) 20251022:Se envio a contratacion con FI Nov 4 20251023: El candidato salio con anotaciones y no se continuara proceso de contratacion. 20251027: Se le solicito al cliente retroalimentacion del proceso. (8) 20251031: GH solicita reclutamiento.20251107: Se enviaron 3 hojas de vida (Lili Nieto, Jessica Armero y Sandra Angulo) (19) 20251209:El cliente envio a evaluar a 3 personas (Leidy Pedrosa, Ricardo Carrillo, Luis Medallo). 20251210:Se enviaron 3 hojas de vida(Jose Fernando Villaquiran, Yesika Robles y Alvaro Solarte) 20251211:GH solicito pruebas para Leidy Pedrosa, Ricardo Carrillo y Luis Medolla. 20251212:Los candidatos aun no han realizado pruebas y tampoco han enviado documentos para enviarlos a estudios de seguridad. 20251215:Los candidato enviaron los documentos y fueron enviados a ES. Pendiente resultados. 20251217:El cliente envio a evlauar a los 3 candidatos. 20251219:Se envio novedad al cliente de resultados de ES. 20251222:Se reunio con el cliente para retroalimentacion de dos de los 3 canddiatos. Lady no se ha podido presentar a entrevista y se volvio a reprogramar para el 23. (6) 20251224: Se evaluo a la candidata y se le dio retroalimentación al cliente. 20251230:Se solicito retroalimentacion. 20260107: Se solicito retroaimentacion y el cliente informa que el dia de mañana tomara una decision. 20260109:El envio evaluar Jose Fernando Villaquiran. 20260114:El cliente envio a contratar a Ricardo con FI 22 Ene. | AL3: =IFERROR(S3/O3,"N/A") -> 1 | AM3: =IFERROR(NETWORKDAYS(D3,Q3,Hoja1!$A$1:$A$29),"N/A") -> 11 | AN3: =IFERROR(NETWORKDAYS(D3,AE3,Hoja1!$A$1:$A$29),"N/A") -> 54 | AO3: 30 | AP3: =AN3-AO3 -> 24 | AQ3: =IFERROR(NETWORKDAYS(AF3,AG3,Hoja1!$A$1:$A$29),"N/A") -> 5 | AR3: 0 | AS3: =AQ3-AR3 -> 5 | AT3: =IFERROR(NETWORKDAYS(D3,AG3,Hoja1!$A$1:$A$29),"N/A") -> 58 | AU3: =AT3-AO3-AR3 -> 28 | AV3: Computrabajo | AW3: GI Group (INSSA) | AX3: Estudio de seguridad | AY3: Estudio de seguridad
A4: 14619 | B4: COOMEVA | C4: EYD | D4: 45972 | E4: 45873 | F4: Cali | G4: DIRECCION NACIONAL | H4: VACANTE DESDE RECLUTAMIENTO | I4: APRENDIZ SENA | J4: ESTUDIANTE/APRENDIZ | K4: Alba Lucy Alape | L4: 1 | M4: Finalizado - Llego hasta contratacion | N4: 0000-00-00 | O4: 10 | P4: No | Q4: 45996 | R4: 46006 | S4: 10 | T4: 0000-00-00 | U4: 0000-00-00 | V4: 0000-00-00 | W4: 0000-00-00 | X4: 0000-00-00 | Y4: 0000-00-00 | Z4: 0000-00-00 | AA4: 2 | AB4: 2 | AC4: 0 | AD4: 46030 | AE4: 46030 | AF4: 46031 | AG4: 46043 | AH4: 46044 | AI4: =MONTH(AH4) -> 1 | AJ4: Valery Palechor Acosta | AK4: 20250808: El cliente solicito reclutamiento. 20250813: Se enviaron 2 hojas de vida (Jhohan y Jhon Sebastian). 20250820:Se solicito retroalimentación 20250821:El cliente informa que realizaran entrevistas el dia Martes 26 de Agosto. 20250827:El cliente informo que el candidato citado no se presento a entrevista por tal razón solicito mas hojas de vida. 20250827:Se enviaron 2 hojas de vida (Jaider y Daniela) 20250902:Se solicito retroalimentación al cliente. 20250903: El cliente informo que esta solicitando espacio para entrevista. 20250915: Pte retro por gh. 20250924: gh envia retro, los candidatos ya no estan disponibles. Se activa reclutamiento. 20251006: Se envian 2 hv. Pte retro por gh. 20251015: gh envia retro, se solicita activar reclutamiento. 20251023: Se envian 2 hv. Pte retro por gh. 20251030: gh envia retro de hv y refiere que se programa a franci para entrevista y se solicita activar reclutamiento. 20251106: Gh solicita evaluar a franci, sin embargo solicita mas reclutamiento. 20251111: se informa a gh que la candidata Franci desiste del proceso. 20251114: Se envian 3 hv. Pte retro por gh. 20251121: gh envia retro y se activa reclutamiento. 20251124: se envian 2 hv. pte retro por gh. 20251125: gh solicita evaluar a contratar a Angela Natalia Ruales . Se programan pruebas. 20251128: Se envia OC FI 10 Dic. 20251204: se notifica a gh que se cancela proceso ya que la institucion no nos envia carta de presentacion. Se activa reclutamiento. 20251205: se envian 3 hv. Pte retro por gh. 20251215: pte retro por gh. 20251226: Pte retro por gh. 20250106: Pte retro por gh. (8) 20260106:gh solicita evaluar a Valery Palechor y solicita activar mas reclutamiento. 20260108: gh solicita avanzar contratacion con Valery Palechor. 20250109: Se envia OC FI 22 Enero. | AL4: =IFERROR(S4/O4,"N/A") -> 1 | AM4: =IFERROR(NETWORKDAYS(D4,Q4,Hoja1!$A$1:$A$29),"N/A") -> 18 | AN4: =IFERROR(NETWORKDAYS(D4,AE4,Hoja1!$A$1:$A$29),"N/A") -> 39 | AO4: 12 | AP4: =AN4-AO4 -> 27 | AQ4: =IFERROR(NETWORKDAYS(AF4,AG4,Hoja1!$A$1:$A$29),"N/A") -> 8 | AR4: 3 | AS4: =AQ4-AR4 -> 5 | AT4: =IFERROR(NETWORKDAYS(D4,AG4,Hoja1!$A$1:$A$29),"N/A") -> 47 | AU4: =AT4-AO4-AR4 -> 32 | AV4: Bolsa de empleo Ins. Educativa | AW4: NA | AX4: Candidato desiste | AY4: Candidato desiste
A5: 14738 | B5: MP | C5: MP | D5: 45986 | E5: 45987 | F5: Cali | G5: CALI | H5: VACANTE DESDE RECLUTAMIENTO | I5: APRENDIZ SENA | J5: ESTUDIANTE/APRENDIZ | K5: Susan Bermeo Saenz | L5: 1 | M5: Finalizado - Llego hasta contratacion | N5: 0000-00-00 | O5: 22 | P5: No | Q5: 45987 | R5: 45987 | S5: 22 | T5: 0000-00-00 | U5: 0000-00-00 | V5: 0000-00-00 | W5: 0000-00-00 | X5: 0000-00-00 | Y5: 0000-00-00 | Z5: 0000-00-00 | AA5: 5 | AB5: 5 | AC5: 0 | AD5: 46009 | AE5: 46010 | AF5: 46010 | AG5: 46024 | AH5: 46027 | AI5: =MONTH(AH5) -> 1 | AJ5: Maria Isabel Epia Perdomo | AK5: 20251125: Se activa reclutamiento. 20251126: Se envian 2 hv pte retro por gh. 20251205: Pte retro por gh. 20251216: pte retro por gh. 20251219:El cliente envio a contratar Maria Isabel Epia con FI Ene 5 | AL5: =IFERROR(S5/O5,"N/A") -> 1 | AM5: =IFERROR(NETWORKDAYS(D5,Q5,Hoja1!$A$1:$A$29),"N/A") -> 2 | AN5: =IFERROR(NETWORKDAYS(D5,AE5,Hoja1!$A$1:$A$29),"N/A") -> 18 | AO5: 3 | AP5: =AN5-AO5 -> 15 | AQ5: =IFERROR(NETWORKDAYS(AF5,AG5,Hoja1!$A$1:$A$29),"N/A") -> 9 | AR5: 3 | AS5: =AQ5-AR5 -> 6 | AT5: =IFERROR(NETWORKDAYS(D5,AG5,Hoja1!$A$1:$A$29),"N/A") -> 26 | AU5: =AT5-AO5-AR5 -> 20 | AV5: Bolsa de empleo Ins. Educativa | AW5: N/A
A6: 14746 | B6: MP | C6: MP | D6: 45891 | E6: 45891 | F6: Cali | G6: CALI | H6: VACANTE DESDE RECLUTAMIENTO | I6: APRENDIZ SENA | J6: ESTUDIANTE/APRENDIZ | K6: Alba Lucy Alape | L6: 1 | M6: Finalizado - Llego hasta contratacion | N6: 0000-00-00 | O6: 8 | P6: No | Q6: 45894 | R6: 45919 | S6: 8 | T6: 0000-00-00 | U6: 0000-00-00 | V6: 0000-00-00 | W6: 0000-00-00 | X6: 0000-00-00 | Y6: 0000-00-00 | Z6: 0000-00-00 | AA6: 1 | AB6: 1 | AC6: 0 | AD6: 45919 | AE6: 46001 | AF6: 46001 | AG6: 46042 | AH6: 46044 | AI6: =MONTH(AH6) -> 1 | AJ6: Saida Tatiana Preciado Dominguez | AK6: 20250822: Se activa reclutamiento. 20250825: Se envian 8 hv para 5 vacantes. Pte retro por gh. 20250902: gh envia retroalimentacion. Se activa reclutamiento. 20250910: Se envian 5 hv. 20250912: Se envian 3 hv pte retro por gh. 20250915: Gh solicita evaluar a Saida Preciado. Se programan pruebas. 20250919: gh solicita avanzar contratacion de Saida Preciado. pte culminar pruebas blusite para enviar OC. 20250925: Se informa a gh por instruccion de juridico que se suspenden las contrataciones de aprendices menores de edad.(52) 20250926: gh solicita activar el proceso con Saida teniendo en cuenta que es referida de Manuel Issa. Se solicita a la candidata realizar tramite para permiso de trabajo para poder enviar a contratacion. 20251209: gh informa que se contratara a Saisa para la segunda fecha de contratacion de Enero. 20251210: Se envia proceso a estudio de seguridad. (8)20251215: gh confirma estudio de seguridad. pte de gh para avanzar proceso. 20251226: Pte retro por gh. 20250106: Pte retro por gh para avanzar contratacion de Saida. 20260114: GH envia aprobacion ministerio, se continua con contratacion para ingreso 22 ene.Se descuentan 22 dias de contratacion, saida estaba realizando proceso de solicitud de permiso de trabajo. | AL6: =IFERROR(S6/O6,"N/A") -> 1 | AM6: =IFERROR(NETWORKDAYS(D6,Q6,Hoja1!$A$1:$A$29),"N/A") -> 2 | AN6: =IFERROR(NETWORKDAYS(D6,AE6,Hoja1!$A$1:$A$29),"N/A") -> 75 | AO6: 60 | AP6: =AN6-AO6 -> 15 | AQ6: =IFERROR(NETWORKDAYS(AF6,AG6,Hoja1!$A$1:$A$29),"N/A") -> 27 | AR6: 22 | AS6: =AQ6-AR6 -> 5 | AT6: =IFERROR(NETWORKDAYS(D6,AG6,Hoja1!$A$1:$A$29),"N/A") -> 101 | AU6: =AT6-AO6-AR6 -> 19 | AV6: Bolsa de empleo Ins. Educativa | AW6: NA
A7: 14875 | B7: BANCOOMEVA | C7: BANCOOMEVA | D7: 45939 | E7: 45911 | F7: Cali | G7: DIRECCION NACIONAL | H7: VACANTE DESDE RECLUTAMIENTO | I7: APRENDIZ SENA | J7: ESTUDIANTE/APRENDIZ | K7: Carolina Cordoba Betancourt | L7: 1 | M7: Finalizado - Llego hasta contratacion | N7: 0000-00-00 | O7: 19 | P7: No | Q7: 46013 | R7: 46013 | S7: 19 | T7: 0000-00-00 | U7: 0000-00-00 | V7: 0000-00-00 | W7: 0000-00-00 | X7: 0000-00-00 | Y7: 0000-00-00 | Z7: 0000-00-00 | AA7: 5 | AB7: 1 | AC7: 0 | AD7: 46031 | AE7: 46035 | AF7: 46035 | AG7: 46043 | AH7: 46044 | AI7: =MONTH(AH7) -> 1 | AJ7: Daniela Murillo Rios | AK7: 20250911: GH solicita reclutamiento perfil contable. 20250916: Se envian 2 HV Katherine, Laura. 20250922: GH solicita evaluar y contratar a Katherine FI 14/10. 20250926: Se informa disponibilidad de informe - Enviar con pruebas completas, GH solicita enviar a contratación cuando complete pruebas. 20251003: Se envia OC FI 14/10. 20251009: Se cancela proceso de contratación de Katherine Rodriguez por novedad en SECAP / Solicita evaluar y contratar a Laura Camila Mosquera FI 22/10 - Se informa a GH que la candidata no se encuentra disponible - Se reinicia reclutamiento. 20251010: Se envian 2 HV Ricardo, Luisa. 20251016: GH informa que los candidatos no se presentan a entrevista programada 15/10 / Se solicita reclutamiento. 20251017: Se envian 2 HV Katherin, Yina. 20251027: Se solicita retroalimentación. 20251028: GH informa que solo se cito a una candidata y no pasa entrevista, se retoma reclutamiento.20251105: se enviaron 3cv a GH.20251114: se realiza seguimiento.20251114: GH informa continaur con candidato Diego Angulo. 20251118: GH informa no continuar con diego Angulo, se activa reclutamiento. 20251124: se envian 2cv a GH.20251202: GH informa dos personas enviadas no se presentaron a entrevista, solicita reclutamiento. 20251204: se envian 2cv a GH Diego, Margi 20251204: candidatos no se ajsutan, deben ser formacion contable. 20251209: se envian 3cv con formacion contable Franyer, cristian, julian 20251216: entrevista lider 15 Dic pdt retro.20251218: GH solicita continuar en evaluacion con Julian Salazar. 20251219: Julian no aprobo veritas, los otros dos estudiantes no aprobaron entrevista, GH solicita reclutamiento. 20251222: se envian 3 cv a GH.20260105: se realiza seguimiento,20260106: GH informa evaluar a Daniela Murillo.20260109: evaluada, 20260113: se envia O.C con F.I 22 Enero. | AL7: =IFERROR(S7/O7,"N/A") -> 1 | AM7: =IFERROR(NETWORKDAYS(D7,Q7,Hoja1!$A$1:$A$29),"N/A") -> 49 | AN7: =IFERROR(NETWORKDAYS(D7,AE7,Hoja1!$A$1:$A$29),"N/A") -> 62 | AO7: 30 | AP7: =AN7-AO7 -> 32 | AQ7: =IFERROR(NETWORKDAYS(AF7,AG7,Hoja1!$A$1:$A$29),"N/A") -> 7 | AR7: 2 | AS7: =AQ7-AR7 -> 5 | AT7: =IFERROR(NETWORKDAYS(D7,AG7,Hoja1!$A$1:$A$29),"N/A") -> 68 | AU7: =AT7-AO7-AR7 -> 36 | AV7: Bolsa de empleo Ins. Educativa | AW7: No aplica | AX7: Estudio de seguridad | AY7: Candidato desiste | AZ7: Prueba integridad
A8: 14883 | B8: MP | C8: MP | D8: 45986 | E8: 45979 | F8: Bogota | G8: BOGOTA | H8: VACANTE DESDE RECLUTAMIENTO | I8: EJECUTIVO/A AFILIACION | J8: CARGO COMERCIAL | K8: Andrea Katherine Angel Moreno | L8: 1 | M8: Finalizado - Llego hasta contratacion | N8: 0000-00-00 | O8: 4 | P8: No | Q8: 45994 | R8: 45994 | S8: 4 | T8: 0000-00-00 | U8: 0000-00-00 | V8: 0000-00-00 | W8: 0000-00-00 | X8: 0000-00-00 | Y8: 0000-00-00 | Z8: 0000-00-00 | AA8: 4 | AB8: 1 | AC8: 0 | AD8: 46009 | AE8: 46009 | AF8: 46009 | AG8: 46031 | AH8: 46035 | AI8: =MONTH(AH8) -> 1 | AJ8: Kevin Mauricio Bolivar Rojas | AK8: 20251020: Se programan entrevistas con JI 22Oct. 20251022: Se realizan entrevistas con JI 2 candidatos no favorables por actitud. Se programan entrevistas 31Oct: Candidatos no se presentan. Se programan entrevistas 05Nov. 20251105: Candidatas seleccionadas ORFA CASTILLO BUSTAMANTE y HELEN VERONICA VÁSQUEZ BELTRAN se solicitan documentos. 20251110: Se solicitan documentos pendientes a las candidatas.HELEN VERONICA VÁSQUEZ BELTRAN desiste del proceso. 20251111: Se solicita ES candidata ORFA CASTILLO BUSTAMANTE fecha de ingreso tentativa 24Nov. 20251112: Candidata no favorable en validación pensional. Se activa reclutamiento. 20251114: Se organizan entrevistas con JI 19Nov. 20251119: Candidata seleccionada BLANCA APONTE SOLER se solicitan documentos. 20251124: Se solicita ES candidata seleccionada fecha tentativa de ingreso 01Dic. 20251125: Candidata no favorable en ES. Se continua reclutamiento. 20251128: Se realizan entrevistas con JI candidata seleccionada INGRI VIVIANA GONZALEZ se solicitan documentos. 20251201: Se solicita ES candidata seleccionada fecha tentativa de ingreso 10Dic. 20251203: Se realizan entrevistas con JI para tener Backup candidato seleccionado Kevin Bolivar se solicitan documentos. 20251205: Candidata viviana desiste. Se continua proceso con backup Kevin a la espera de documentos. 20251209: Se le indica al candidato documentos faltantes. 20251216: Se solicita excepción de estudios a GH. 20251218: Se solicita ES candidato KEVIN BOLIVAR fecha tentativa de ingreso 05Ene. 20251231: Se congela proceso de contratación por directriz nacional. 20260105: Se recibe aval para continuar con la contratación fecha tentativa de ingreso 13Ene. | AL8: =IFERROR(S8/O8,"N/A") -> 1 | AM8: =IFERROR(NETWORKDAYS(D8,Q8,Hoja1!$A$1:$A$29),"N/A") -> 7 | AN8: =IFERROR(NETWORKDAYS(D8,AE8,Hoja1!$A$1:$A$29),"N/A") -> 17 | AO8: 2 | AP8: =AN8-AO8 -> 15 | AQ8: =IFERROR(NETWORKDAYS(AF8,AG8,Hoja1!$A$1:$A$29),"N/A") -> 15 | AR8: 10 | AS8: =AQ8-AR8 -> 5 | AT8: =IFERROR(NETWORKDAYS(D8,AG8,Hoja1!$A$1:$A$29),"N/A") -> 31 | AU8: =AT8-AO8-AR8 -> 19 | AV8: Computrabajo | AW8: Colmédica
A9: 14926 | B9: MP | C9: MP | D9: 45994 | E9: 45918 | F9: Cali | G9: DIRECCION NACIONAL | H9: VACANTE DESDE RECLUTAMIENTO | I9: ESTUDIANTE EN PRACTICA | J9: ESTUDIANTE/APRENDIZ | K9: Alba Lucy Alape | L9: 1 | M9: Finalizado - Llego hasta contratacion | N9: 0000-00-00 | O9: 9 | P9: No | Q9: 45996 | R9: 46007 | S9: 9 | T9: 0000-00-00 | U9: 0000-00-00 | V9: 0000-00-00 | W9: 0000-00-00 | X9: 0000-00-00 | Y9: 0000-00-00 | Z9: 0000-00-00 | AA9: 3 | AB9: 2 | AC9: 0 | AD9: 46013 | AE9: 46013 | AF9: 46013 | AG9: 46024 | AH9: 46027 | AI9: =MONTH(AH9) -> 1 | AJ9: Maria Paula Perez Fernandez | AK9: 20250919: Se activa reclutamiento. 20250922: Se envian 3 hv. Pte retro por gh. 20251003: gh solicita evaluar a Santiago y activar reclutamiento. 20251006: se envian 3 hv. 20251007: se notifica a gh que santiago no realiza pruebas. pte retro de las hv enviadas. 20251027: pte retro por gh. 20251105: gh envia retro y solicita activar reclutamiento. 20251111: Se envian 3 hv. Pte retro por gh. 20251113: Se envia 1 hv adicional referida por Manuel Issa. Pte retro por gh. 20251120: gh solicita evaluar a Daniela y Luisa Bastidas. Se programan pruebas. 20251127: se confirma informe. 20251128: gh aolicita avanzar contratacion con Daniela. 20251201: Se envia OC FI 10 DIC. 20251203: se cancela proceso con Daniela, por que la candidata no le brindaran carta de presentacion. Se activa reclutamiento. 20251205: se envian 3 hv pte retro por gh. 20251215: Pte retro por gh. 20251216: gh solicita evaluar a Maria Paula Perez. Se programan pruebas. 20251222: Se confirma informe y se envia OC FI 05 ENE. | AL9: =IFERROR(S9/O9,"N/A") -> 1 | AM9: =IFERROR(NETWORKDAYS(D9,Q9,Hoja1!$A$1:$A$29),"N/A") -> 3 | AN9: =IFERROR(NETWORKDAYS(D9,AE9,Hoja1!$A$1:$A$29),"N/A") -> 13 | AO9: 0 | AP9: =AN9-AO9 -> 13 | AQ9: =IFERROR(NETWORKDAYS(AF9,AG9,Hoja1!$A$1:$A$29),"N/A") -> 8 | AR9: 3 | AS9: =AQ9-AR9 -> 5 | AT9: =IFERROR(NETWORKDAYS(D9,AG9,Hoja1!$A$1:$A$29),"N/A") -> 20 | AU9: =AT9-AO9-AR9 -> 17 | AV9: Bolsa de empleo Ins. Educativa | AW9: NA | AX9: Candidato desiste | AY9: Candidato desiste
A10: 14967 | B10: COOMEVA | C10: GCGIA | D10: 45958 | E10: 45979 | F10: Caribe | G10: BARRANQUILLA | H10: EMPRESA ENVIA EL CANDIDATO | I10: GESTOR/A COOPERATIVO ESPECIALIZADO | J10: CARGO COMERCIAL | K10: Sheylin Florez Saenz | L10: 1 | M10: Finalizado - Llego hasta contratacion | N10: 0000-00-00 | O10: 1 | Q10: 0000-00-00 | R10: 0000-00-00 | S10: 1 | T10: 0000-00-00 | U10: 0000-00-00 | V10: 0000-00-00 | W10: 0000-00-00 | X10: 0000-00-00 | Y10: 0000-00-00 | Z10: 0000-00-00 | AA10: 3 | AB10: 3 | AC10: 0 | AD10: 45986 | AE10: 46003 | AF10: 46006 | AG10: 46024 | AH10: 46027 | AI10: =MONTH(AH10) -> 1 | AJ10: Vanessa Donado Aguas | AK10: 20251029: REQ preventiva. JI y GH revisan candidatos entrevistados en vacante de EC para esta oferta. 20251107: Piden evaluar candidata Melanie Cerpa Cabrera en RQ preventiva. 20251111: GH comparte candidatas de Banco a tener en cuenta en el proceso: Sandra Arteta, Ibis ortega y Vanessa Donado. 20251114: GH Solicita agendar entrevistas con las 3 candidatas de Banco y Melanie Cerpa (Externa) para el 18/Nov. 20251119: JI Solicita avanzar a pruebas con Sandra, Ibis y Vanessa. Melanie no pudo asistir y sera reprogramada. 20251125: Se comparte Informes a JI de cand Sandra Arteta, Ibis Ortega y Vanessa Donado (Melanie no continua por cirugia). 20251128: GH solicita avanzar EDS con Sandra Arteta Arteta. 20251202: Se comparte a contratacion para incio de EDS. 20251204: Se confirma EDS favorable. A espera de indicacion para inicio de contratacion. 20251212: GH confirma que candidata Sandra Artera desiste del proceso y da aval para enviar a EDS a Vanessa Donado Aguas. 20251215: Se comparte a EDS candidata Vanessa Donado Aguas con FI 5/Ene. 20260102: Contratacion confirma ingreso de Vanessa Donado Aguas con FI 05/01/2026. | AL10: =IFERROR(S10/O10,"N/A") -> 1 | AM10: =IFERROR(NETWORKDAYS(D10,Q10,Hoja1!$A$1:$A$29),"N/A") -> N/A | AN10: =IFERROR(NETWORKDAYS(D10,AE10,Hoja1!$A$1:$A$29),"N/A") -> 31 | AO10: 0 | AP10: =AN10-AO10 -> 31 | AQ10: =IFERROR(NETWORKDAYS(AF10,AG10,Hoja1!$A$1:$A$29),"N/A") -> 13 | AR10: 8 | AS10: =AQ10-AR10 -> 5 | AT10: =IFERROR(NETWORKDAYS(D10,AG10,Hoja1!$A$1:$A$29),"N/A") -> 44 | AU10: =AT10-AO10-AR10 -> 36 | AV10: Referido cliente | AW10: Bancoomeva | AX10: Candidato desiste
A11: 14987 | B11: MP | C11: MP | D11: 45957 | E11: 45931 | F11: Medellin | G11: MEDELLIN | H11: VACANTE DESDE RECLUTAMIENTO | I11: AUXILIAR ENFERMERIA | J11: SALUD/ASISTENCIAL | K11: Francy Giraldo Santos | L11: 1 | M11: Finalizado - Llego hasta contratacion | N11: 0000-00-00 | O11: 14 | P11: No | Q11: 45959 | R11: 45959 | S11: 14 | T11: 0000-00-00 | U11: 0000-00-00 | V11: 0000-00-00 | W11: 0000-00-00 | X11: 0000-00-00 | Y11: 0000-00-00 | Z11: 0000-00-00 | AA11: 4 | AB11: 4 | AC11: 0 | AD11: 45995 | AE11: 46003 | AF11: 46003 | AG11: 46013 | AH11: 46027 | AI11: =MONTH(AH11) -> 1 | AJ11: Luisa Fernanda Vasquez Care | AK11: 20251002: Se activa reclutamiento. 20251002: Se le compartieron 7 hojas de vida para la validacion del cliente. 20251006: Pendiente de retroalimentacion del cliente. 20251014: Las personas enviadas ya no estan disponibles el dia de hoy se comparten 5 hojas de vida para la validacion del cliente. 200251017: El cliente solicita avanzar proceso con Laura Gomez y con Mateo Baena. 20251020: Se esta en proceso evaluativo con los 2 candidatos mencionados. 20251022: Se evalua a Laura Gomez. para esta RQ. 20251024: Se envia a contratacion a la candidata si todo sale ok su ingreso seria el 4 de noviembre 20251027: La candidata Laura se retira del proceso por que le progamaron una cirugia. SE REACTIVA PROCESO. 20251029: Se comparten 7 hojas de vida. 20251106: Pendiente retroalimentacion del cliente. 20251110: Pendiente por retroalimentación por parte de cliente . 20251118: La rq se detiene ya que la jefe de el CM esta en capacitacion en cali . 20251128: La rq se encuentra suspendida por directriz del cliente. 20251202: Se le comparte al cliente un correo para que nos retroalimente de la rq 20251203: El cliente solicita avanzar con 2 candidatas para fase evaluativa . 20251209: El cliente da el aval para avanzar a fase final con Luisa Fernanda Vasquez para ingreso el 5 de enero . 20251215: La candidata se encuentra en EM ya que solo hasta hoy tenia disponibildiad. | AL11: =IFERROR(S11/O11,"N/A") -> 1 | AM11: =IFERROR(NETWORKDAYS(D11,Q11,Hoja1!$A$1:$A$29),"N/A") -> 3 | AN11: =IFERROR(NETWORKDAYS(D11,AE11,Hoja1!$A$1:$A$29),"N/A") -> 32 | AO11: 19 | AP11: =AN11-AO11 -> 13 | AQ11: =IFERROR(NETWORKDAYS(AF11,AG11,Hoja1!$A$1:$A$29),"N/A") -> 7 | AR11: 2 | AS11: =AQ11-AR11 -> 5 | AT11: =IFERROR(NETWORKDAYS(D11,AG11,Hoja1!$A$1:$A$29),"N/A") -> 38 | AU11: =AT11-AO11-AR11 -> 17 | AV11: Computrabajo | AW11: METROSALUD | AX11: Candidato desiste | AY11: Candidato desiste
A12: 15009 | B12: BANCOOMEVA | C12: BANCOOMEVA | D12: 45966 | E12: 45933 | F12: Bogota | G12: BOGOTA | H12: VACANTE DESDE RECLUTAMIENTO | I12: APRENDIZ SENA | J12: ESTUDIANTE/APRENDIZ | K12: Andrea Katherine Angel Moreno | L12: 1 | M12: Finalizado - Llego hasta contratacion | N12: 0000-00-00 | O12: 5 | P12: No | Q12: 45997 | R12: 45997 | S12: 5 | T12: 0000-00-00 | U12: 0000-00-00 | V12: 0000-00-00 | W12: 0000-00-00 | X12: 0000-00-00 | Y12: 0000-00-00 | Z12: 0000-00-00 | AA12: 5 | AB12: 1 | AC12: 0 | AD12: 46027 | AE12: 46027 | AF12: 46027 | AG12: 46045 | AH12: 46048 | AI12: =MONTH(AH12) -> 1 | AJ12: Eillen Tatiana Garzon Guzman | AK12: 20251006: Se activa reclutamiento. 20251009: Se organiza entrevista candidato Daniel Felipe Pancha 15oct. 20251015: Candidato preseleccionado, sin embargo tiene contrato activo con el sena que esta intentando descargar por error en la plataforma. Se continua reclutamiento. 20251021: Se realizan entrevistas con JI candidata seleccionada Maria Jose Cardenas. Se solicitan documentos. 20251024: Candidata con contrato activo en el SENA solicita cadena de formación para dar continuidad. Se continua reclutamiento. 20251028: Se realizan entrevistas con JI candidato seleccionado ESTEBAN URDANETA se solicitan documentos. 20251031: Se solicitan documentos pendientes. 20251105: Candidato desiste del proceso. Se activa reclutamiento. 20251107: Se continua reclutamiento. 20251110: Se continua reclutamiento. 20251118: Se continua reclutamiento. 20251125: Se continua reclutamiento. 20251202: Se continua en reclutamiento. 20251205: Se realiza entrevista a Jhon Marroquin y Eillen Tatiana Garzón Guzmán desde la USC se valida agenda con GH para entrevista. 20251209: Gh indica agendar entrevista en hora de la tarde 09Dic. 20251210: Se solicitan documentos a la candidata Eillen Tatiana Garzón Guzmán, candidato Jhon Marronquin desiste. 20251212: Se le indica a la candidata documentos pendientes. 20251216: Se le solicita a la candidata documentos pendientes. 20251218: Se le informa a la candidata agilizar carta de fechas. 20251222: A la espera de registro en caprendizaje para carta de fechas. 20251226: Candidata solicita a la institución cambio de documento de TI a CC. A la espera del cambio por parte de la institución. 20251231: A la espera de cambio de documento en la plataforma del sena. 20260105: Se solicita ES candidata seleccionada Eillen Tatiana Garzón Guzmán fecha tentativa de ingreso 13Ene. 20260113: Candidata no puede ingresar, pendiente de actutlización en la plataforma sena para generar la carta de fechas. 20260115: Se le solicita a la candidata agilizar el tema para posible ingreso 22Ene. 20260122: La institución genera carta de fechas. Se solicita a contratación activar ingreso 23Ene. *+Se descuentan 12 dias al proceso de selección por demoras en la carta de fechas y actualización en el sena, se descuentan 8 días al proceso de contratación por demora en la carta de fechas** | AL12: =IFERROR(S12/O12,"N/A") -> 1 | AM12: =IFERROR(NETWORKDAYS(D12,Q12,Hoja1!$A$1:$A$29),"N/A") -> 22 | AN12: =IFERROR(NETWORKDAYS(D12,AE12,Hoja1!$A$1:$A$29),"N/A") -> 40 | AO12: 11 | AP12: =AN12-AO12 -> 29 | AQ12: =IFERROR(NETWORKDAYS(AF12,AG12,Hoja1!$A$1:$A$29),"N/A") -> 14 | AR12: 9 | AS12: =AQ12-AR12 -> 5 | AT12: =IFERROR(NETWORKDAYS(D12,AG12,Hoja1!$A$1:$A$29),"N/A") -> 53 | AU12: =AT12-AO12-AR12 -> 33 | AV12: Computrabajo | AW12: Sin experiencia | AX12: Candidato desiste
A13: 15014 | B13: COOMEVA | C13: GCGIA | D13: 45936 | E13: 45936 | F13: Bogota | G13: BOGOTA | H13: VACANTE DESDE RECLUTAMIENTO | I13: ESTUDIANTE EN PRACTICA | J13: ESTUDIANTE/APRENDIZ | K13: Paola Andrea Molano Malaver | L13: 1 | M13: Finalizado - Llego hasta contratacion | N13: 0000-00-00 | O13: 3 | P13: Si | Q13: 45989 | R13: 45989 | S13: 3 | T13: 0000-00-00 | U13: 0000-00-00 | V13: 0000-00-00 | W13: 0000-00-00 | X13: 0000-00-00 | Y13: 0000-00-00 | Z13: 0000-00-00 | AA13: 4 | AB13: 1 | AC13: 0 | AD13: 45985 | AE13: 45985 | AF13: 46013 | AG13: 46024 | AH13: 46027 | AI13: =MONTH(AH13) -> 1 | AJ13: Juana Sofia Sanchez Dueñas | AK13: 20251007: se inicia reclutamiento 20251015: Se agenda entrevista con JI, candidatos no se presentan 20251016: se continúa con reclutamiento 20251022: se agenda entrevista con JI 20251105: En reclutamiento 20251113: En reclutamiento 20251119: Entrevista con JI con 4 practicantes 20251120: Se solicita documentos 20251124: Se envia a juanita Gomez a ES, Mientras la universidad nos envia la carta de aval 20251202: continuamos a la espera de la carta de aval, practicante indica que la semana del 20 la universidad le entrega la carta apenas se matriculé.Ingreso 5 de enero | AL13: =IFERROR(S13/O13,"N/A") -> 1 | AM13: =IFERROR(NETWORKDAYS(D13,Q13,Hoja1!$A$1:$A$29),"N/A") -> 37 | AN13: =IFERROR(NETWORKDAYS(D13,AE13,Hoja1!$A$1:$A$29),"N/A") -> 33 | AO13: 0 | AP13: =AN13-AO13 -> 33 | AQ13: =IFERROR(NETWORKDAYS(AF13,AG13,Hoja1!$A$1:$A$29),"N/A") -> 8 | AR13: 2 | AS13: =AQ13-AR13 -> 6 | AT13: =IFERROR(NETWORKDAYS(D13,AG13,Hoja1!$A$1:$A$29),"N/A") -> 59 | AU13: =AT13-AO13-AR13 -> 57 | AV13: Computrabajo | AW13: Sin experiencia
A14: 15053 | B14: COOMEVA | C14: BANCOOMEVA USC | D14: 45966 | E14: 45944 | F14: Cali | G14: DIRECCION NACIONAL | H14: CONCURSO MIXTO | I14: AUXILIAR DIGITALIZACIÓN | J14: AUXILIAR/OPERATIVO | K14: Susan Bermeo Saenz | L14: 1 | M14: Finalizado - Llego hasta contratacion | N14: 0000-00-00 | O14: 3 | P14: No | Q14: 45968 | R14: 45980 | S14: 3 | T14: 0000-00-00 | U14: 45968 | V14: 45979 | W14: 0000-00-00 | X14: 0000-00-00 | Y14: 0000-00-00 | Z14: 0000-00-00 | AA14: 1 | AB14: 1 | AC14: 0 | AD14: 45994 | AE14: 46008 | AF14: 46009 | AG14: 46027 | AH14: 46027 | AI14: =MONTH(AH14) -> 1 | AJ14: Adriana Morales Urbano | AK14: 20251105: El cliente solicito concurso mixto. 20251107: Se envio publicacion interna. del 13 a 18 de Nov. 20251111: Se enviaron 3 hojas de vida externas (Maria Muñoz, Carolina Gutierrez, Karol Villa) 20251118: Se solicito retroalimentacion. 20251119: El cliente cito a entrevista para el Lunes 24 de Nov. 20251126:Se solicito retroalimentacion. 20251127:El cliente solicito evaluar a Adriana Morales quien se encuentra realizando su practica en la compañia. Se enviaron pruebas y se cito a entrevista para el Martes 2 de Diciembre.20251203:Se subio informe y se le informo al cliente. 20251209:Se solicito retroalimentacion. 20251212:aun no informan como se va a proceder con el proceso. 20251215: Se solicito informacion de como proceder con el proceso. (8) 20251217: El cliente solicito contratar a Adriana 20251218:Se envio a contratar con FI Enero 5. | AL14: =IFERROR(S14/O14,"N/A") -> 1 | AM14: =IFERROR(NETWORKDAYS(D14,Q14,Hoja1!$A$1:$A$29),"N/A") -> 3 | AN14: =IFERROR(NETWORKDAYS(D14,AE14,Hoja1!$A$1:$A$29),"N/A") -> 29 | AO14: 6 | AP14: =AN14-AO14 -> 23 | AQ14: =IFERROR(NETWORKDAYS(AF14,AG14,Hoja1!$A$1:$A$29),"N/A") -> 11 | AR14: 5 | AS14: =AQ14-AR14 -> 6 | AT14: =IFERROR(NETWORKDAYS(D14,AG14,Hoja1!$A$1:$A$29),"N/A") -> 40 | AU14: =AT14-AO14-AR14 -> 29 | AV14: Referido cliente | AW14: Menzies Aviación Colombia
A15: 15059 | B15: COOMEVA | C15: USC | D15: 45946 | E15: 45946 | F15: Cali | G15: DIRECCION NACIONAL | H15: VACANTE DESDE RECLUTAMIENTO | I15: APRENDIZ SENA | J15: ESTUDIANTE/APRENDIZ | K15: Susan Bermeo Saenz | L15: 1 | M15: Finalizado - Llego hasta contratacion | N15: 0000-00-00 | O15: 5 | P15: No | Q15: 46017 | R15: 45971 | S15: 5 | T15: 0000-00-00 | U15: 0000-00-00 | V15: 0000-00-00 | W15: 0000-00-00 | X15: 0000-00-00 | Y15: 0000-00-00 | Z15: 0000-00-00 | AA15: 1 | AB15: 1 | AC15: 0 | AD15: 46027 | AE15: 46036 | AF15: 46036 | AG15: 46042 | AH15: 46044 | AI15: =MONTH(AH15) -> 1 | AJ15: Edwin Fernando Nieves Quiñonez | AK15: 20251016: El cliente solicito reclutamiento de aprendices de SST. 20251020:Se enviaron 3 hojas de vida (Meily Tumbo, Juan Carlos Luna, Isabella Gutierrez) 20251024:Se solicito retroalimentacion. 20251028: El cliente no ha dado retroalimentacion. 20251030:Se volvio a solicitar retroalimentacion. 20251104: Se solicto nuevamente retroalimentacion. 20251107:El cliente aun no da retroalimentacion, se volvio a preguntar. 20251110: GH entrevistara esta semana. 20251113:Se solicito retroalimentacion. 20251114: GH informa que esta a la espera de fecha y hora de entrevistas por parte del lider. 20251118: Se volvio a solicitar retroalimentacion. 20251119: GH informa que esta a la espera de fecha y hora de entrevistas por parte del lider. 20251121:Se volvio a solicitar retroalimentacion. 20251124: Se envio correo informando que se va a detener el proceso. 20251128: GH Informa que los candidatos ya no se estan disponibles. Se envio correo solicitando que se debe de gestionar las entrevistas mas rapido ya que los aprendices se ajustan rapido. 20251201:Se activa reclutamiento. 20251202:Se enviaron 2 hojas de vida (Maria Jose Hurtado, Giseth Rodriguez) 20251205:Se solicito retroalimentacion. 20251210:Se solicito retroalimentacion. 20251212:aun no dan retroalimentacion. 20251224:Se solicito retroalimentacion. El cliente informa que las canddiatas ya esta realizando practicas. 20251226:Se activa reclutamiento. 20251226:El cliente solicito evaluar a Edwin nieves, candidato que se habia enviado para la RQ 15283. Ya no sera perfil SST y se contratara con esta RQ. 20250105:Se subio informe y se le informo al cliente. 20260113:Se solicito nuevamente retroalimentacion de la evaluacion realizada a edwin. 20260114:El cliente envio a contratar a Edwin. Se envio a contratacion con FI 22 Ene. | AL15: =IFERROR(S15/O15,"N/A") -> 1 | AM15: =IFERROR(NETWORKDAYS(D15,Q15,Hoja1!$A$1:$A$29),"N/A") -> 48 | AN15: =IFERROR(NETWORKDAYS(D15,AE15,Hoja1!$A$1:$A$29),"N/A") -> 59 | AO15: =23+13 -> 36 | AP15: =AN15-AO15 -> 23 | AQ15: =IFERROR(NETWORKDAYS(AF15,AG15,Hoja1!$A$1:$A$29),"N/A") -> 5 | AR15: 0 | AS15: =AQ15-AR15 -> 5 | AT15: =IFERROR(NETWORKDAYS(D15,AG15,Hoja1!$A$1:$A$29),"N/A") -> 63 | AU15: =AT15-AO15-AR15 -> 27 | AV15: Bolsa de empleo Ins. Educativa | AW15: N/A
A16: 15068 | B16: COOMEVA | C16: GCGIA | D16: 45945 | E16: 45945 | F16: Caribe | G16: RIOHACHA | H16: VACANTE DESDE RECLUTAMIENTO | I16: APRENDIZ SENA | J16: ESTUDIANTE/APRENDIZ | K16: Sheylin Florez Saenz | L16: 1 | M16: Finalizado - Llego hasta contratacion | N16: 0000-00-00 | O16: 6 | P16: No | Q16: 45993 | R16: 45993 | S16: 6 | T16: 0000-00-00 | U16: 0000-00-00 | V16: 0000-00-00 | W16: 0000-00-00 | X16: 0000-00-00 | Y16: 0000-00-00 | Z16: 0000-00-00 | AA16: 1 | AB16: 1 | AC16: 0 | AD16: 46013 | AE16: 46013 | AF16: 46013 | AG16: 46038 | AH16: 46044 | AI16: =MONTH(AH16) -> 1 | AJ16: Zharick Dalais Amaya Orellano | AK16: 20251015: Crean RQ - Posiciòn ocupada hasta el 01/Nov. 20251020: Las instituciones informan que aùn no cuentan con estudiantes inscritos en productiva. 20251114: En reunion de seguimiento se solicita revisar aprendices en Riohacha con posibilidad de pasar la posicion para esa ciudad. 20251124: Sena comparte 4 aprendices. Entrevistas programadas 25/nov para posicion de Riohacha en proceso de gestion. 20251125: Candidatos no avanzan y se comparte 1 candidato : Natanael Ipuana. 20251202: Se comparten candidatos: Zharick Amaya y Ana Fuentes quienes seran entrevistados el 4/Dic.20251209: JI salio a vacaciones sin dar retroalimentacion de las entrevistas programadas. 20251215: JI confirma que no avanzan los dos aprendices. Se retoma reclutamiento. 20251222: GH confirma avanzar en evaluacion con Zharick Dalais Amaya Orellano. Pend cambio de ciudad de Sincelejo a Riohacha. 20260108: Se comparte Zharick Dalais Amaya a contratacion para inicio de EDS con FI 22/Ene. 20260115: Candidata Zharick Dalais Amaya se encuentra en aprobacion de oferta. 20260116: confirman contratacion de Zharik Dalais Amaya con FI 22/01/2026 | AL16: =IFERROR(S16/O16,"N/A") -> 1 | AM16: =IFERROR(NETWORKDAYS(D16,Q16,Hoja1!$A$1:$A$29),"N/A") -> 33 | AN16: =IFERROR(NETWORKDAYS(D16,AE16,Hoja1!$A$1:$A$29),"N/A") -> 46 | AO16: 8 | AP16: =AN16-AO16 -> 38 | AQ16: =IFERROR(NETWORKDAYS(AF16,AG16,Hoja1!$A$1:$A$29),"N/A") -> 17 | AR16: 12 | AS16: =AQ16-AR16 -> 5 | AT16: =IFERROR(NETWORKDAYS(D16,AG16,Hoja1!$A$1:$A$29),"N/A") -> 62 | AU16: =AT16-AO16-AR16 -> 42 | AV16: Busqueda directa | AW16: N/A
A17: 15074 | B17: MP | C17: MP | D17: 45946 | E17: 45946 | F17: Caribe | G17: SANTA MARTA | H17: VACANTE DESDE RECLUTAMIENTO | I17: EJECUTIVO/A AFILIACION | J17: CARGO COMERCIAL | K17: Norma Elena Achkar Mansour | L17: 1 | M17: Finalizado - Llego hasta contratacion | N17: 0000-00-00 | O17: 12 | P17: No | Q17: 46007 | R17: 46007 | S17: 12 | T17: 0000-00-00 | U17: 0000-00-00 | V17: 0000-00-00 | W17: 0000-00-00 | X17: 0000-00-00 | Y17: 0000-00-00 | Z17: 0000-00-00 | AA17: 2 | AB17: 1 | AC17: 0 | AD17: 46027 | AE17: 46027 | AF17: 46027 | AG17: 46031 | AH17: 46035 | AI17: =MONTH(AH17) -> 1 | AJ17: Katty Johanna Castillo Acosta | AK17: 20251016: Crean RQ. 20251021: Se comparten: Vianys - Karen. 20251028: Se solicita informaciòn de avance. 20251029: Solicitan evaluar a Vianys. 20251107: Candidata desiste. 20251118: Se programa con Lìder entrega de candidatos para el 18/Nov. 20251120: Se comparten 4 candidatos para cubrir 2 vacantes: Indira - Marisella - Julieth - Sayuris. 20251202: Piden evaluar a Indira en la RQ 14942 y piden ver mas candidatos para esta RQ. 20251204: Se comparten: Eduardo - Luis - Ana. 20251209: Candidato Luis en entrevista con Lìder. 20251216: se comparte terna Sebastian Muñoz, Katty Castillo y Liliana Imitola. 20251218: GH solicita avanzar proceso evaluativo con Katty Johana Castillo Acosta. 20251224: Candidata Katty Castillo tiene pendiente una prueba. 20260105: Se comparte registro evaluativo y se avanza con EDS. 20260106: Congelan contrataciones - GH tramita aval para ingreso al 13//Ene. 20260107: Candidata en EMO. 20260109: Se confirma contratación de la colaboradora Katty Johanna Castillo Acosta, con FI. 13/01/2026. | AL17: =IFERROR(S17/O17,"N/A") -> 1 | AM17: =IFERROR(NETWORKDAYS(D17,Q17,Hoja1!$A$1:$A$29),"N/A") -> 41 | AN17: =IFERROR(NETWORKDAYS(D17,AE17,Hoja1!$A$1:$A$29),"N/A") -> 53 | AO17: 11 | AP17: =AN17-AO17 -> 42 | AQ17: =IFERROR(NETWORKDAYS(AF17,AG17,Hoja1!$A$1:$A$29),"N/A") -> 5 | AR17: 0 | AS17: =AQ17-AR17 -> 5 | AT17: =IFERROR(NETWORKDAYS(D17,AG17,Hoja1!$A$1:$A$29),"N/A") -> 57 | AU17: =AT17-AO17-AR17 -> 46 | AV17: Magneto | AW17: CLARO MOVIL
A18: 15077 | B18: COOMEVA | C18: USC | D18: 45946 | E18: 45946 | F18: Cali | G18: DIRECCION NACIONAL | H18: VACANTE DESDE RECLUTAMIENTO | I18: APRENDIZ SENA | J18: ESTUDIANTE/APRENDIZ | K18: Susan Bermeo Saenz | L18: 1 | M18: Finalizado - Llego hasta contratacion | N18: 0000-00-00 | O18: 6 | P18: No | Q18: 45966 | R18: 45971 | S18: 6 | T18: 0000-00-00 | U18: 0000-00-00 | V18: 0000-00-00 | W18: 0000-00-00 | X18: 0000-00-00 | Y18: 0000-00-00 | Z18: 0000-00-00 | AA18: 2 | AB18: 1 | AC18: 0 | AD18: 46031 | AE18: 46035 | AF18: 46035 | AG18: 46044 | AH18: 46045 | AI18: =MONTH(AH18) -> 1 | AJ18: Paula Andrea Cadena Quintero | AK18: 20251016:El cliente solicito estudiantes de Call Center del insitituto PIO. 20251020:El instituto respondio que no cuentan actualmente con estudiantes en etapa practica. Se le informo al cliente y se le envio informacion de otras insitutciones que cuentan con el programa pero actualmente no tienen estudiantes disponbibles. 20251024: Se le envio al cliente correo con el estudio realizado acerca de las instituciones que ofrecen programas de Call Center y que actualmente no cuentan con estudiantes disponibles.(12) 20251030: El cliente solicito aprendices en etapa lectiva. 20251030: El cliente solicito aprendices en etapa lectiva. 20251105: Se enviaron 3 hojas de vida (Angela del Carmen Sanchez, Erika Murillo, Yuly Ordoñez) 20251110:El cliente entrevistara esta semana. 20251113:Se solicito retroalimentacion. 20251118: se solicito retroalimentacion. 20251120: Se volvio a solicitar retroalimentacion 20251124:Se envio correo solicitando retroalimentacion. (14) 20251127:El cliente envio a evaluar a Angela del Carmen. Se enviaron pruebas y se cito a entrevista para el Martes 2 de Diciembre. 20251201:Se envio una hoja de vida (Deysi Garcia) 20251202:La candidata no paso prueba veritas. 20251205:Se solicito retroalimentacion. 20251210:Se solicito retroalimentacion. 20251215:se solicito nuevamente retroalimentacion de la hv enviada el 1 de diciembre, (10) 20251217:El cliente solicito mas hojas de vida ya que la candidata no paso entrevista. 20251224: se activo Reclutamiento. 20260102:Se enviaron 3 hv Paula Andrea Cadena, Johan Manquillo, Paula Gutierrez. 20260106:El cliente envio a evaluar a Paula Cadena. Se enviaron pruebas y se cito a entrevista para el Jueves 8 Enero. 20260109:Se subio informe y se le informo al cliente. 20260113:El cliente envio a contratar a Paula Cadena. Se envio a contratacion con FI 22 ENE. | AL18: =IFERROR(S18/O18,"N/A") -> 1 | AM18: =IFERROR(NETWORKDAYS(D18,Q18,Hoja1!$A$1:$A$29),"N/A") -> 14 | AN18: =IFERROR(NETWORKDAYS(D18,AE18,Hoja1!$A$1:$A$29),"N/A") -> 58 | AO18: 36 | AP18: =AN18-AO18 -> 22 | AQ18: =IFERROR(NETWORKDAYS(AF18,AG18,Hoja1!$A$1:$A$29),"N/A") -> 8 | AR18: 3 | AS18: =AQ18-AR18 -> 5 | AT18: =IFERROR(NETWORKDAYS(D18,AG18,Hoja1!$A$1:$A$29),"N/A") -> 65 | AU18: =AT18-AO18-AR18 -> 26 | AV18: Bolsa de empleo Ins. Educativa | AW18: N/A
A19: 15095 | B19: MP | C19: MP | D19: 45951 | E19: 45951 | F19: Caribe | G19: CARTAGENA | H19: VACANTE DESDE RECLUTAMIENTO | I19: APRENDIZ SENA | J19: ESTUDIANTE/APRENDIZ | K19: Sheylin Florez Saenz | L19: 1 | M19: Finalizado - Llego hasta contratacion | N19: 0000-00-00 | O19: 7 | P19: No | Q19: 46000 | R19: 46000 | S19: 7 | T19: 0000-00-00 | U19: 0000-00-00 | V19: 0000-00-00 | W19: 0000-00-00 | X19: 0000-00-00 | Y19: 0000-00-00 | Z19: 0000-00-00 | AA19: 1 | AB19: 1 | AC19: 0 | AD19: 46009 | AE19: 46009 | AF19: 46009 | AG19: 46022 | AH19: 46027 | AI19: =MONTH(AH19) -> 1 | AJ19: Cristina Isabel Hadechini Perez | AK19: 20251021: Crean RQ. 20251023: Se comparten: Silvana - Divisai. 20251028: Se solicita informaciòn de avance. 20251111: GH pide al lìder agendar espacio para entrevista. 20251112: Se suma dupla: Lineth - Yorleidys - GH informa que las entrevistas son el 19/Nov. 20251119: Piden nuevos candidatos. 20251121: Se comparten: Yengil - Roximar. 20251125: Se solicitan informaciòn de avance. 20251201: Se solicita informaciòn de avance. 20251202: Informan que el Lìder entrevistarà despues del cierre de mes. 20251204: Descartan candidatos. 20251209: Se comparten: Nikolas - Cristina -Jesus. 20251212: Se envia a proceso evaluativo a Cristina. 20251218: Se avanza con EDS 20251231: Se confirma contratación de la estudiante Cristina Isabel Hadechini Perez, con FI. 05/01/2026. | AL19: =IFERROR(S19/O19,"N/A") -> 1 | AM19: =IFERROR(NETWORKDAYS(D19,Q19,Hoja1!$A$1:$A$29),"N/A") -> 33 | AN19: =IFERROR(NETWORKDAYS(D19,AE19,Hoja1!$A$1:$A$29),"N/A") -> 40 | AO19: 20 | AP19: =AN19-AO19 -> 20 | AQ19: =IFERROR(NETWORKDAYS(AF19,AG19,Hoja1!$A$1:$A$29),"N/A") -> 9 | AR19: 4 | AS19: =AQ19-AR19 -> 5 | AT19: =IFERROR(NETWORKDAYS(D19,AG19,Hoja1!$A$1:$A$29),"N/A") -> 48 | AU19: =AT19-AO19-AR19 -> 24 | AV19: Busqueda directa | AW19: N/A
A20: 15106 | B20: MP | C20: MP | D20: 45973 | E20: 45953 | F20: Caribe | G20: BARRANQUILLA | H20: VACANTE DESDE RECLUTAMIENTO | I20: EJECUTIVO/A AFILIACION | J20: CARGO COMERCIAL | K20: Norma Elena Achkar Mansour | L20: 1 | M20: Finalizado - Llego hasta contratacion | N20: 0000-00-00 | O20: 3 | P20: Si | Q20: 45986 | R20: 45986 | S20: 3 | T20: 0000-00-00 | U20: 0000-00-00 | V20: 0000-00-00 | W20: 0000-00-00 | X20: 0000-00-00 | Y20: 0000-00-00 | Z20: 0000-00-00 | AA20: 2 | AB20: 2 | AC20: 0 | AD20: 46003 | AE20: 46003 | AF20: 46003 | AG20: 46010 | AH20: 46027 | AI20: =MONTH(AH20) -> 1 | AJ20: Mayra Isabel Torres Bayona | AK20: 20251023: Crean RQ - Solicitan evaluar a Ellen Gonzalez quien habìa estado en proceso el 2023. 20251028: Candidata Pte por Veritas. 20251030: Se solicita aval para validar Bachiller toda vez que la candidata no cuenta con otros estudios. 20251106: Comparten exepciòn por formaciòn. 20251107: Se comparte reporte evaluativo y se avanzar con ES. 20251110: Se comparte novedad en bases - Piden ampliaciòn. 20251118: Se confima el no avance del proceso - Se comparten: Natalia - Alfredo - Freddy. 20251124: Solicitan nuevos candidatos. 20251125: Se comparten: Erick - Laura - Mayra. 20251201: Se solicita informaciòn de avance. 20251202: Informan que el lìder entrevistara despues del cierre de mes. 20251205: Solicitan evaluar a Mayra Torres. 20251212: Se comparte registro evaluativo y se avanza con EDS. 20251219: Se confirma contratación de la candidata Mayra Isabel Torres Bayona, con FI. 05/01/2026 | AL20: =IFERROR(S20/O20,"N/A") -> 1 | AM20: =IFERROR(NETWORKDAYS(D20,Q20,Hoja1!$A$1:$A$29),"N/A") -> 9 | AN20: =IFERROR(NETWORKDAYS(D20,AE20,Hoja1!$A$1:$A$29),"N/A") -> 21 | AO20: 4 | AP20: =AN20-AO20 -> 17 | AQ20: =IFERROR(NETWORKDAYS(AF20,AG20,Hoja1!$A$1:$A$29),"N/A") -> 6 | AR20: 2 | AS20: =AQ20-AR20 -> 4 | AT20: =IFERROR(NETWORKDAYS(D20,AG20,Hoja1!$A$1:$A$29),"N/A") -> 26 | AU20: =AT20-AO20-AR20 -> 20 | AV20: Computrabajo | AW20: Seguros Bolivar | AX20: Estudio de seguridad
A21: 15144 | B21: COOMEVA | C21: USC | D21: 45967 | E21: 45961 | F21: Cali | G21: DIRECCION NACIONAL | H21: CONCURSO INTERNO | I21: INGENIERO/A GESTIÓN DE LA INFORMACIÓN | J21: ANALISTA/PROFESIONAL/COORDINADOR | K21: Susan Bermeo Saenz | L21: 1 | M21: Finalizado - Llego hasta contratacion | N21: 0000-00-00 | O21: 0 | Q21: 0000-00-00 | R21: 0000-00-00 | S21: 0 | T21: 0000-00-00 | U21: 45968 | V21: 45980 | W21: 0000-00-00 | X21: 0000-00-00 | Y21: 0000-00-00 | Z21: 0000-00-00 | AA21: 3 | AB21: 3 | AC21: 0 | AD21: 46013 | AE21: 46027 | AF21: 46028 | AG21: 46045 | AH21: 46045 | AI21: =MONTH(AH21) -> 1 | AJ21: Javier Acosta Muñoz | AK21: 20251031: El cliente solicito reclutamiento. 20251106:El cliente cambio el proceso y solicito solo recltuamiento interno y publicar el concurso hasta el Viernes 14 de Noviembre. (4) 20251107:Se envio concurso interno. 20251119: Se confirmo filtro interno 20251124:Se solicito retroalimentacion. 20251201:Se solicito retroalimentación. 20251202:El cliente informa que realizaron pruebas tecnicas y apenas tengan resultados estaran citando a entrevista. 20251209:Se volvio a solicitar retroalimentacion. (13) 20251211:El cliente envio a evaluar a Javier Acosta, Santiago Gomez y Caroline Ibagos. 20251215:Santiago y Javier no han terminado pruebas. Se cito a entrevista a Caroline que ya realizo las pruebas. 20251217:Santiago Gomez y Caroline no han terminado pruebas, por tal razón no se ha podido subir los informes. (2) 20251222:Se subio informes y se le informo al cliente. (5) 20251230:Se solicito retroalimentacion. 20260105:El cliente envio a contratar a Javier Acosta. 20260106:Se envio a contratacion con FI 22 Enero | AL21: =IFERROR(S21/O21,"N/A") -> N/A | AM21: =IFERROR(NETWORKDAYS(D21,Q21,Hoja1!$A$1:$A$29),"N/A") -> N/A | AN21: =IFERROR(NETWORKDAYS(D21,AE21,Hoja1!$A$1:$A$29),"N/A") -> 39 | AO21: 16 | AP21: =AN21-AO21 -> 23 | AQ21: =IFERROR(NETWORKDAYS(AF21,AG21,Hoja1!$A$1:$A$29),"N/A") -> 13 | AR21: 8 | AS21: =AQ21-AR21 -> 5 | AT21: =IFERROR(NETWORKDAYS(D21,AG21,Hoja1!$A$1:$A$29),"N/A") -> 52 | AU21: =AT21-AO21-AR21 -> 28 | AV21: Movimiento Interno | AW21: Coomeva Cooperativa
A22: 15147 | B22: BANCOOMEVA | C22: BANCOOMEVA | D22: 45957 | E22: 45957 | F22: Cali | G22: DIRECCION NACIONAL | H22: CONCURSO INTERNO | I22: ANALISTA SERVICIOS GESTION HUMANA | J22: ANALISTA/PROFESIONAL/COORDINADOR | K22: Carolina Cordoba Betancourt | L22: 1 | M22: Finalizado - Llego hasta contratacion | N22: 0000-00-00 | O22: 0 | Q22: 0000-00-00 | R22: 0000-00-00 | S22: 0 | T22: 0000-00-00 | U22: 45958 | V22: 45968 | W22: 0000-00-00 | X22: 0000-00-00 | Y22: 0000-00-00 | Z22: 46010 | AA22: 2 | AB22: 2 | AC22: 0 | AD22: 46017 | AE22: 46024 | AF22: 46027 | AG22: 46031 | AH22: 46035 | AI22: =MONTH(AH22) -> 1 | AJ22: Juan David Duque Gutierrez | AK22: 20251022:GH solicita concurso mixto sin RQ por nuevo cargo. 20251027:Gh crea RQ y envia 5 hv para ofertar, ademas se agrega al perfil manejo de excel, por lo que se reinicia reclutamiento. 20251028: se envian links para publicar concurso del 31 oct al 5 nov. 20251029: se envian 4 hv de reclutamiento. 20251107: se confirmar candidatos internos a GH para revisión. 20251110: se enviaran candidatos de magneto el 11nov. 20251120: se realiza seguimiento.20251201: se realiza seguimiento.20251209: se realiza seguimiento.20251212: GH programa prueba tecnica.20251219: GH solicita evaluar Jessica y Juan Duque. 20251226: Se carga evaluacion en SF.20260102: GH solicita envia a contratacion Juan Duque. 20260105: se envia O.C F.I 13 Enero | AL22: =IFERROR(S22/O22,"N/A") -> N/A | AM22: =IFERROR(NETWORKDAYS(D22,Q22,Hoja1!$A$1:$A$29),"N/A") -> N/A | AN22: =IFERROR(NETWORKDAYS(D22,AE22,Hoja1!$A$1:$A$29),"N/A") -> 45 | AO22: 22 | AP22: =AN22-AO22 -> 23 | AQ22: =IFERROR(NETWORKDAYS(AF22,AG22,Hoja1!$A$1:$A$29),"N/A") -> 5 | AR22: 0 | AS22: =AQ22-AR22 -> 5 | AT22: =IFERROR(NETWORKDAYS(D22,AG22,Hoja1!$A$1:$A$29),"N/A") -> 50 | AU22: =AT22-AO22-AR22 -> 28 | AV22: Movimiento Interno | AW22: Coomeva UCO
A23: 15153 | B23: COOMEVA | C23: UTTD | D23: 45936 | E23: 46019 | F23: Cali | G23: DIRECCION NACIONAL | H23: VACANTE DESDE RECLUTAMIENTO | I23: INGENIERO/A RPA | J23: ANALISTA/PROFESIONAL/COORDINADOR | K23: Alba Lucy Alape | L23: 1 | M23: Finalizado - Llego hasta contratacion | N23: 0000-00-00 | O23: 4 | P23: Si | Q23: 45939 | R23: 45994 | S23: 4 | T23: 0000-00-00 | U23: 0000-00-00 | V23: 0000-00-00 | W23: 0000-00-00 | X23: 0000-00-00 | Y23: 0000-00-00 | Z23: 0000-00-00 | AA23: 3 | AB23: 3 | AC23: 0 | AD23: 46001 | AE23: 46007 | AF23: 46013 | AG23: 46024 | AH23: 46027 | AI23: =MONTH(AH23) -> 1 | AJ23: Cristian Fernando Vallejo Gonzalez | AK23: 20251006: GH solicita reclutamiento con nuevo salario. 20251009: Se envian 4 hv. Pte retro por gh. 20251028: Pte retro por gh. 20251110: Pte retro por gh. 20251114: Pte retro por gh. 20251118: gh envia a Nicolas Palacio para ofertar vacante. 20251120: se confirma oferta de candidato pte retro por gh. 20251202: Pte retro por gh. (33) 20251203: gh solicita evaluar a Nicolas Palacio, Cristian Villavicencio y Cristian Vallejo. Se programan pruebas. 20251210: se confirman informes. 20251215: pte retro por gh. 20251216: gh solicita avanzar contratacion con Cristian Vallejo FI 05 ENE. 20251218: pte completar documentos para enviar OC. 20251222: Se completa documentos y se envia OC FI 05 ENE. | AL23: =IFERROR(S23/O23,"N/A") -> 1 | AM23: =IFERROR(NETWORKDAYS(D23,Q23,Hoja1!$A$1:$A$29),"N/A") -> 4 | AN23: =IFERROR(NETWORKDAYS(D23,AE23,Hoja1!$A$1:$A$29),"N/A") -> 48 | AO23: 33 | AP23: =AN23-AO23 -> 15 | AQ23: =IFERROR(NETWORKDAYS(AF23,AG23,Hoja1!$A$1:$A$29),"N/A") -> 8 | AR23: 3 | AS23: =AQ23-AR23 -> 5 | AT23: =IFERROR(NETWORKDAYS(D23,AG23,Hoja1!$A$1:$A$29),"N/A") -> 59 | AU23: =AT23-AO23-AR23 -> 23 | AV23: Computrabajo | AW23: CONSTRUCTORA BOLIVAR
